Workbook

Sheet MENU-OLD
A1: PHP DEVELOPER WISE ARN TGT VS ACV
A2: SL NO. | B2: DEVLOPER NAME | C2: DEVELOPER HISTORY | D2: TEAM LEAD | E2: LANGUAGE | F2: WORK LOCATION | G2: CONTACT | H2: TGT LAST DATE | I2: ACT LAST DATE | J2: PROB END DT | K2: T SAVE | L2: TOTAL | M2: =COUNTA(E3:E51) -> 36
A3: 1 | B3: Amit Mishra | C3: AMIT MISHRA'!A1 | D3: SANDEEP | E3: PHP | F3: OFFICE | G3: 90780 75643 | H3: =MAX('AMIT MISHRA'!$J$3:$J$1009) -> 45104 | I3: =MAX('AMIT MISHRA'!$L$3:$L$1009) -> 45096 | J3: =MAX('AMIT MISHRA'!$N$3:$N$1009) -> 45103 | K3: =+'AMIT MISHRA'!Q1 -> -79 | L3: PHP | M3: =COUNTIF($E$3:$E$52,L3) -> 22
A4: 2 | B4: Banita kumari swain | C4: BANITA KU SWAIN'!A1 | D4: SANDEEP | E4: PHP | F4: WFH | G4: 90780 84117 | H4: =MAX('BANITA KU SWAIN'!$K$3:$K$965) -> 45412 | I4: =MAX('BANITA KU SWAIN'!$M$3:$M$965) -> 45404 | J4: =MAX('BANITA KU SWAIN'!$O$3:$O$965) -> 45374 | K4: =+'BANITA KU SWAIN'!R1 -> -174 | L4: PYTHON | M4: =COUNTIF($E$3:$E$36,L4) -> 2
A5: 3 | B5: Gayatri Gochhayat | C5: GAYATRI GOCHHAYAT'!A1 | D5: SANDEEP | E5: PHP | F5: OFFICE | G5: 90780 84119 | H5: =MAX('GAYATRI GOCHHAYAT'!$K$3:$K$944) -> 45444 | I5: =MAX('GAYATRI GOCHHAYAT'!$M$3:$M$944) -> 45441 | J5: =MAX('GAYATRI GOCHHAYAT'!$O$3:$O$944) -> 45427 | K5: =+'GAYATRI GOCHHAYAT'!R1 -> -111 | L5: DESIGN | M5: =COUNTIF($E$3:$E$30,L5) -> 2
A6: 4 | B6: Jyotirani Panda | C6: JYOTIRANI PANDA'!A1 | D6: JYOTIRANI | E6: PHP | F6: OFFICE | G6: 74400 12310 | H6: =MAX('JYOTIRANI PANDA'!$K$3:$K$1114) -> 45448 | I6: =MAX('JYOTIRANI PANDA'!$M$3:$M$1114) -> 45442 | J6: =MAX('JYOTIRANI PANDA'!$O$3:$O$1114) -> 45436 | K6: =+'JYOTIRANI PANDA'!R1 -> -90 | L6: ANDROID | M6: =COUNTIF($E$3:$E$30,L6) -> 1
A7: 5 | B7: Krushna Ch Sahoo | C7: KRUSHNA CH SAHOO'!A1 | D7: KRUSHNA | E7: PHP | F7: OFFICE | G7: 90780 79614 | H7: =MAX('KRUSHNA CH SAHOO'!$J$3:$J$1031) -> 45037 | I7: =MAX('KRUSHNA CH SAHOO'!$L$3:$L$1031) -> 45077 | J7: =MAX('KRUSHNA CH SAHOO'!$N$3:$N$1031) -> 45058 | K7: =+'KRUSHNA CH SAHOO'!Q1 -> -49 | L7: Coordination | M7: =COUNTIF($E$3:$E$45,L7) -> 2
A8: 6 | B8: Puja Verma | C8: PUJA VERMA'!A1 | D8: JYOTIRANI | E8: PHP | F8: WFH | G8: 89269 73952 | H8: =MAX('PUJA VERMA'!$L$3:$L$1072) -> 45443 | I8: =MAX('PUJA VERMA'!$N$3:$N$1072) -> 45440 | J8: =MAX('PUJA VERMA'!$P$3:$P$1072) -> 45421 | K8: =+'PUJA VERMA'!S1 -> -189 | L8: Testing | M8: =COUNTIF($E$3:$E$48,L8) -> 0
A9: 7 | B9: Sandeep Jena | C9: SANDEEP JENA'!A1 | D9: SANDEEP | E9: PHP | F9: OFFICE | G9: 93376 42361 | H9: =MAX('SANDEEP JENA'!$J$3:$J$1001) -> 45105 | I9: =MAX('SANDEEP JENA'!$L$3:$L$1001) -> 45134 | J9: =MAX('SANDEEP JENA'!$N$3:$N$1001) -> 45108 | K9: =+'SANDEEP JENA'!Q1 -> -64 | L9: DOT NET | M9: =COUNTIF($E$3:$E$48,L9) -> 1
A10: 8 | B10: Snigdha S. Tripathy | C10: SNIGDHA S TRIPATHY'!A1 | D10: UMESH M | E10: PHP | F10: OFFICE | H10: =MAX('SNIGDHA S TRIPATHY'!$L$3:$L$1099) -> 45446 | I10: =MAX('SNIGDHA S TRIPATHY'!$N$3:$N$1099) -> 45442 | J10: =MAX('SNIGDHA S TRIPATHY'!$P$3:$P$1099) -> 45575 | K10: =+'SNIGDHA S TRIPATHY'!S1 -> 94
A11: 9 | B11: Souvik Paik | C11: SOUVIK PAIK'!A1 | D11: KRUSHNA | E11: PHP | F11: OFFICE | G11: 77354 13179 | H11: =MAX('SOUVIK PAIK'!$K$3:$K$1080) -> 45444 | I11: =MAX('SOUVIK PAIK'!$M$3:$M$1080) -> 45442 | J11: =MAX('SOUVIK PAIK'!$O$3:$O$1080) -> 45433 | K11: =+'SOUVIK PAIK'!R1 -> -42
A12: 10 | B12: Sradha Suman | C12: SRADHA S BEHERA'!A1 | D12: UMESH M | E12: PHP | F12: OFFICE | G12: 90780 74812 | H12: =MAX('SRADHA S BEHERA'!$K$163:$K$1155) -> 0 | I12: =MAX('SRADHA S BEHERA'!$M$5:$M$1155) -> 45435 | J12: =MAX('SRADHA S BEHERA'!$O$163:$O$1155) -> 0 | K12: =+'SRADHA S BEHERA'!R1 -> #VALUE!
A13: 11 | B13: Subham Behera | C13: SUBHAM BEHERA'!A1 | D13: KRUSHNA | E13: PHP | F13: OFFICE | G13: 63729 10485 | H13: =MAX('SUBHAM BEHERA -MIS'!$J$2:$J$1099) -> 45443 | I13: =MAX('SUBHAM BEHERA -MIS'!$L$2:$L$1099) -> 45436 | J13: =MAX('SUBHAM BEHERA -MIS'!$N$2:$N$1099) -> 45414 | K13: =+'SUBHAM BEHERA -MIS'!Q1 -> -92
A14: 12 | B14: Subhankar Tripathy | C14: SUBHANKAR TRIPATHY'!A1 | D14: SRADHA | E14: PHP | F14: WFH | H14: =MAX('SUBHANKAR TRIPATHY'!$J$2:$J$1004) -> 45166 | I14: =MAX('SUBHANKAR TRIPATHY'!$L$2:$L$1008) -> 45196 | J14: =MAX('SUBHANKAR TRIPATHY'!$N$2:$N$1008) -> 45166 | K14: =+'SUBHANKAR TRIPATHY'!Q1 -> -77
A15: 13 | B15: Sitesh moharana | C15: SITESH MOHARANA'!A1 | D15: SUBHAM | E15: PHP | F15: OFFICE | G15: 90780 79609 | H15: =MAX(SITESH!$K$2:$K$1094) -> 45570 | I15: =MAX(SITESH!$M$3:$M$1095) -> 45439 | J15: =MAX(SITESH!$O$3:$O$1095) -> 45413 | K15: =+SITESH!R1 -> -107
A16: 14 | B16: Satyabrata jati | C16: SATYABRATA JATI'!A1 | D16: SUBHAM | E16: PHP | F16: OFFICE | G16: 98533 83400 | H16: =MAX('SATYABRATA JATI-MIS'!$I$3:$I$1014) -> 45085 | I16: =MAX('SATYABRATA JATI-MIS'!$K$3:$K$1014) -> 45087 | J16: =MAX('SATYABRATA JATI-MIS'!$M$3:$M$1014) -> 45087 | K16: =+'SATYABRATA JATI-MIS'!P1 -> -12
A17: 15 | B17: Truptirani Behera | C17: TRUPTIRANI BEHERA'!A1 | D17: JYOTIRANI | E17: PHP | F17: OFFICE | G17: 90780 84118 | H17: =MAX('TRUPTIRANI BEHERA'!$I$3:$I$1010) -> 45126 | I17: =MAX('TRUPTIRANI BEHERA'!$L$3:$L$1010) -> 45156 | J17: =MAX('TRUPTIRANI BEHERA'!$N$3:$N$1010) -> 45092 | K17: ='TRUPTIRANI BEHERA'!Q1 -> -137
A18: 16 | B18: Umesh Majhi | C18: UMESH MAJHI'!A1 | D18: UMESH M | E18: PHP | F18: OFFICE | G18: https://t.me/umeshmjhi | H18: =MAX('UMESH MAJHI'!$K$7:$K$1082) -> 47268 | I18: =MAX('UMESH MAJHI'!$M$3:$M$1082) -> 45570 | J18: =MAX('UMESH MAJHI'!$O$7:$O$1082) -> 45540 | K18: =+'UMESH MAJHI'!R1 -> -39
A19: 17 | B19: Jyostnamayee Nayak | C19: JYOSTNAMAYEE NAYAK'!A1 | D19: GAYATRI | E19: PHP | F19: WFH | G19: 75048 89447 | H19: =MAX('JYOSTNAMAYEE NAYAK'!$J$3:$J$1019) -> 45435 | I19: =MAX('JYOSTNAMAYEE NAYAK'!$L$3:$L$1019) -> 45433 | J19: =MAX('JYOSTNAMAYEE NAYAK'!$N$3:$N$1019) -> 0 | K19: =+'JYOSTNAMAYEE NAYAK'!Q1 -> -201
A20: 18 | B20: Deenabandhu Dakua | C20: DEENABANDHU DAKUA'!A1 | D20: KRUSHNA | E20: DESIGN | F20: OFFICE | G20: 92373 03661 | H20: =MAX('DEENABANDHU DAKUA'!$K$2:$K$1131) -> 45444 | I20: =MAX('DEENABANDHU DAKUA'!$M$2:$M$1131) -> 45442 | J20: =MAX('DEENABANDHU DAKUA'!$O$2:$O$1131) -> 45421 | K20: =+'DEENABANDHU DAKUA'!R1 -> -96
A21: 19 | B21: Shakti Darshan Behera | D21: SANJIT | E21: DESIGN | F21: OFFICE
A22: 20 | B22: Miki Pradhan | E22: PHP | F22: OFFICE
A23: 21 | B23: Chetan Pradhan | E23: PHP | F23: OFFICE
A24: 22 | B24: Sreedhar Panigrahi | E24: PHP | F24: OFFICE
A25: 23 | B25: Chinmayee Majhi | E25: PHP | F25: OFFICE
A26: 24 | B26: Rakesh Kumar Dash | E26: PHP | F26: OFFICE
A27: 25 | B27: Sunila Kumar Dash | D27: UMESH M | E27: ANDROID | F27: OFFICE | G27: 90780 82272
A28: 27 | B28: Santosh Nayak | D28: SANJIT | E28: DOT NET | F28: OFFICE
A29: 27 | B29: Sibaprasad Behera | D29: AMIT M | E29: PYTHON | F29: OFFICE | G29: https://t.me/Sibaprasad65
A30: 28 | B30: Sunil Kumar Pattanaik | D30: AMIT M | E30: PYTHON | F30: WFH
A31: 30 | B31: Bibhudatta Triripathy | D31: AMIT M | E31: LEFT | F31: PYTHON
A32: 29 | B32: Chinmayee Panda | D32: AMIT M | E32: LEFT | F32: PYTHON
A33: 26 | B33: Prangyashree Das | D33: UMESH M | E33: LEFT | F33: ANDROID | G33: 92373 03662
A34: 31 | B34: Kalyani Priyadarshini | C34: KALYANI PRIYADARSHINI'!A1 | D34: UMESH M | E34: LEFT | F34: PHP | G34: 90780 75636 | H34: =MAX('KALYANI PRIYADARSHINI'!$J$3:$J$997) -> #REF! | I34: =MAX('KALYANI PRIYADARSHINI'!$L$3:$L$997) -> 44981 | J34: =MAX('KALYANI PRIYADARSHINI'!$N$3:$N$997) -> #REF! | K34: =+'KALYANI PRIYADARSHINI'!Q1 -> -45
A35: 32 | B35: Smita Mishra | C35: SMITA MISHRA'!A1 | D35: UMESH M | E35: LEFT | F35: PHP | H35: =MAX('SMITA MISHRA'!$H$3:$H$1002) -> 44865 | I35: =MAX('SMITA MISHRA'!$J$3:$J$1002) -> 0 | K35: =+'SMITA MISHRA'!M1 -> 0
A37: 33 | B37: Sushanta Mohapatra | E37: Coordination | F37: Office
A38: 34 | B38: Jitendra Kumar Jena | E38: FULL STACK | F38: Office
A39: 35 | B39: Rakesh Biswal | F39: LEFT
A40: 36 | B40: Soumya Mohapatra | E40: Coordination | F40: Office

Sheet DEVELOPER  INFO
A1: PHP DEVELOPER WISE DEVELOPMENT HISTORY
A2: SL NO. | B2: DEVLOPER NAME | C2: DEVELOPER HISTORY | D2: CATEGORY | E2: TEAM LEAD | F2: CURRENT TEAM | G2: LANGUAGE | H2: WORK LOCATION | I2: CONTACT | J2: WORK STAGE | K2: CURRENT WORK DETAIL | L2: TGT START DATE | M2: TG END DATE | N2: ACT START DATE | O2: T SAVE
A3: 1 | B3: RAHUL ROUT | E3: Jyotirani | G3: ANDROID | H3: OFFICE | I3: 83430 33946 | K3: Material Internal Request | L3: 45439 | M3: 45444 | N3: 45439
A4: 2 | B4: Gayatri Gochhayat | C4: GAYATRI GOCHHAYAT'!A1 | D4: ERP | E4: Gayatri | F4: MIS | G4: PHP | H4: OFFICE | I4: 90780 84119 | K4: counting for new pending approval | L4: 45440 | M4: 45444 | N4: 45439 | O4: ='GAYATRI GOCHHAYAT'!R1 -> -111
A5: 3 | B5: Sreedhar Panigrahi | C5: SREEDHAR | D5: ERP | E5: Gayatri | F5: MIS | G5: PHP | H5: OFFICE | K5: Pending count function creation with old sql query optimization of (Tender, Purchase, Expense) For new pending approval | L5: 45443 | M5: 45448 | N5: 45443 | O5: =SREEDHAR!R1 -> -63
A6: 4 | B6: Sailesh Dakua | D6: ERP | E6: Gayatri | F6: M RULES | G6: PHP | H6: OFFICE | K6: Output gst report of collection modules El listing, and analyse of the work. | L6: 45428 | M6: 45434 | N6: 45428 | O6: ='SAILESH DAKUA'!R1 -> -255
A7: 5 | B7: Rakesh Kumar Dash | C7: RAKESH KUMAR | D7: ERP | E7: Gayatri | F7: M RULES | G7: PHP | H7: OFFICE | K7: Solving issues of manage creditor and testing in dev | L7: 45443 | M7: 45446 | N7: 45443 | O7: =RAKESH!S3 -> -108
A8: 6 | B8: Jyostnamayee Nayak | C8: JYOSTNAMAYEE NAYAK'!A1 | D8: ERP | E8: Gayatri | F8: M RULES | G8: PHP | H8: WFH | I8: 75048 89447 | K8: Modification in getremark ,getapprovalremark,totalpendingcount function in approvalmatrix function page | L8: 45433 | M8: 45435 | N8: 45433 | O8: ='JYOSTNAMAYEE NAYAK'!Q1 -> -201
A9: 7 | B9: Sitesh moharana | C9: SITESH MOHARANA'!A1 | D9: ERP | E9: Jyotirani | F9: M RULES | G9: PHP | H9: OFFICE | I9: 90780 79609 | K9: Fraction of unit entry and calculation at time of PI to EI convertion. | L9: 45434 | M9: 45443 | N9: 45434 | O9: =SITESH!R1 -> -107
A10: 8 | B10: Snigdha S. Tripathy | C10: SNIGDHA S TRIPATHY'!A1 | D10: ERP | E10: Jyotirani | F10: M RULES | G10: PHP | H10: OFFICE | K10: All 5 module dpr to show attendance status of all employee in dpr section | L10: 45443 | M10: 45445 | N10: 45443 | O10: ='SNIGDHA S TRIPATHY'!S1 -> 94
A11: 9 | B11: Puja Verma | C11: PUJA VERMA'!A1 | D11: ERP | E11: Jyotirani | F11: M RULES | G11: PHP | H11: OFFICE | I11: 89269 73952 | K11: Order Receipt second phase functionality Implement | L11: 45440 | M11: 45443 | N11: 45440 | O11: ='PUJA VERMA'!S1 -> -189
A12: 10 | B12: Souvik Paik | C12: SOUVIK PAIK'!A1 | D12: API | E12: Jyotirani | F12: MIS & CMC | G12: PHP | H12: OFFICE | I12: 77354 13179 | K12: working on blogs section of iyro solar website | L12: 45443 | M12: 45444 | N12: 45443 | O12: ='SOUVIK PAIK'!R1 -> -42
A13: 11 | B13: Jyotirani Panda | C13: JYOTIRANI PANDA'!A1 | D13: ERP | E13: Jyotirani | F13: MIS & CMC | G13: PHP | H13: OFFICE | I13: 74400 12310 | K13: Close job order cancel part and vender assign part implementation. | L13: 45444 | M13: 45446 | N13: 45444 | O13: ='JYOTIRANI PANDA'!R1 -> -90
A14: 12 | B14: Chetan Pradhan | C14: CHETAN PRADHAN | D14: ERP | E14: Sradha Suman | F14: M RULES | G14: PHP | H14: OFFICE | K14: 2nd Stage implementation in expense module of payment request . | L14: 45442 | M14: 45447 | N14: 45442 | O14: =CHETAN!R1 -> -236
A15: 13 | B15: Jagannath Prasad Kar | D15: ERP | E15: Sradha Suman | G15: PHP | H15: OFFICE | K15: DEV COMPLETE | O15: =JAGANNATH!O1 -> -11
A16: 14 | B16: Sradha Suman | C16: SRADHA S BEHERA'!A1 | D16: ERP | E16: Sradha Suman | F16: MIS & CMC | G16: PHP | H16: OFFICE | I16: 90780 74812 | K16: Approval access change in multiple section in live server(manual attendance, Leave apply , Leave cancel, OD) | L16: 45441 | M16: 45442 | N16: 45442 | O16: ='SRADHA S BEHERA'!P3 -> 437
A17: 15 | B17: Subham Behera | C17: SUBHAM BEHERA'!A1 | D17: Manufecturing | E17: Sradha Suman | G17: PHP | H17: OFFICE | I17: 63729 10485 | K17: Store stock report of manufacturing project. | L17: 45440 | M17: 45443 | N17: 45441 | O17: ='SUBHAM BEHERA -MIS'!Q1 -> -92
A18: 16 | B18: Deenabandhu Dakua | C18: DEENABANDHU DAKUA'!A1 | D18: ERP | E18: Umesh Majhi | G18: DESIGN | H18: OFFICE | I18: 92373 03661 | K18: Designing of Factory Creation List page in manufacturing ERP. | L18: 45443 | M18: 45444 | N18: 45443 | O18: ='DEENABANDHU DAKUA'!R1 -> -96
A19: 17 | B19: Shakti Darshan Behera | C19: SHAKTI DESIGN | D19: ERP | E19: Sradha Suman | G19: DESIGN | H19: OFFICE | I19: 8908363107 | K19: DEV COMPLETE | O19: =SHAKTI!Q1 -> -187
A20: 18 | B20: Umesh Majhi | C20: UMESH MAJHI'!A1 | D20: ERP | E20: Umesh Majhi | F20: MIS & CMC | G20: PHP | H20: OFFICE | I20: https://t.me/umeshmjhi | K20: Implement parallel approval in PO Term in dev server | L20: 45443 | M20: 45444 | N20: 45443 | O20: ='UMESH MAJHI'!R1 -> -39
A21: 19 | B21: Dipti Ranjan Barik | C21: DEEPTI | D21: ERP | E21: Umesh Majhi | G21: PHP | H21: OFFICE | K21: Solving issue of Supplier Enquiry Page | L21: 45442 | M21: 45443 | N21: 45442 | O21: =DEEPTI!R2 -> -374
A22: 20 | B22: Chinmayee Majhi | C22: CHINMAYEE | D22: ERP | E22: Sanjaya Kumar Rout | F22: M RULES | G22: PHP | H22: OFFICE | K22: Backend change request work for ERP complain module | L22: 45439 | M22: 45444 | N22: 45440 | O22: ='CHINMAYEE M'!S2 -> -114
A23: 21 | B23: Satya Swarup | C23: SATYASWARUP | D23: ERP | E23: Sanjaya Kumar Rout | F23: M RULES | G23: PHP | H23: OFFICE | K23: Working on pending PO amounts and store PO amount as per discussion | L23: 45428 | M23: 45434 | N23: 45429 | O23: =SATYASWARUP!R2 -> -155
A24: 22 | B24: Bikash Pradhan | D24: ERP | E24: Sanjaya Kumar Rout | G24: PHP | H24: OFFICE | K24: Loan advance Dynamical approval and 2nd stage design | L24: 45444 | M24: 45447 | N24: 45444 | O24: =BIKASH!R2 -> -132
A25: 23 | B25: Sanjaya Kumar Rout | C25: SANJAY KU ROUT' | D25: ERP | E25: Sanjaya Kumar Rout | F25: MIS & CMC | G25: PHP | H25: OFFICE | K25: Function part modification in Deduction part with implement in Local System. | L25: 45434 | M25: 45435 | N25: 45434 | O25: ='SANJAY KU ROUT'!R2 -> -150
A26: 24 | B26: Jitendra Kumar Jena | G26: PHP | H26: OFFICE | I26: 9337642362
A27: 25 | B27: Santosh Nayak | D27: Moneymela | E27: Prabodh Dash | G27: DOT NET | H27: OFFICE | I27: 8882357266 | K27: Issue Resolve On Lender Management | L27: 45442 | M27: 45443 | N27: 45442 | O27: ='SANTOSH NAYAK'!R1 -> -72
A28: 26 | B28: Ratnajit Singh | D28: Moneymela | E28: Prabodh Dash | G28: DOT NET | H28: OFFICE | K28: Issue fixing In Employee Registration time Aadhar number field. Also in upload document field age proof name and in the drop down PAN Card | L28: 45444 | M28: 45444 | N28: 45444 | O28: ='RATNAJEET SINGH'!R1 -> -39
A29: 27 | B29: Sabita | E29: Prabodh Dash | G29: Coordination | H29: OFFICE | K29: MoneyMela Testing & ERP KT Acceptance
A30: 28 | B30: Sushanta Mohapatra | E30: Sushant Mohaptra | G30: Coordination | H30: OFFICE | I30: 74400 12108 | K30: Multi task
A31: 29 | B31: Soumya Mohapatra | E31: Sushant Mohaptra | G31: Coordination | H31: OFFICE | I31: 9078074801 | K31: Multi task
A32: 30 | B32: Janmejaya Giri | E32: Sushant Mohaptra | G32: Coordination | H32: OFFICE | K32: Multi task
A33: 31 | B33: Soumitra Kumar Sahoo | E33: Sushant Mohaptra | G33: Coordination | H33: OFFICE | K33: MoneyMela Testing & ERP KT Acceptance
A36: 1 | B36: Bunty Das | G36: RESIGNED | H36: Coordination
A37: 2 | B37: Pabitra Kumar Sethi | G37: RESIGNED | H37: Outsourcing | I37: 6372910479
A38: 3 | B38: Rakesh Biswal | G38: RESIGNED | H38: QA TESTING
A39: 4 | B39: Sunila Kumar Dash | G39: RESIGNED | H39: ANDROID | I39: 90780 82272 | J39: 1ST STAGE
A40: 5 | B40: Prangyashree Das | G40: RESIGNED | H40: ANDROID | I40: 92373 03662
A41: 6 | B41: Sunil Kumar Pattanaik | G41: RESIGNED | H41: PYTHON | I41: 8260839694
A42: 7 | B42: Bibhudatta Triripathy | G42: RESIGNED | H42: PYTHON
...

Sheet SANTOSH NAYAK
P1: =SUM(P3:P1055) -> 51 | Q1: =SUM(Q3:Q1055) -> 123 | R1: =SUM(R3:R1055) -> -72
A2: SL.NO. | B2: MODULE | C2: SUB MODULE | D2: ACTIVITIES | E2: WORK TYPE | F2: STATUS | G2: APPROVAL | H2: RESTRICTION | I2: NOTIFICATION | J2: TGT ST DATE | K2: TGT END DATE | L2: ACT ST DATE | M2: ACT END DATE | N2: PROB ST DT | O2: PROB END DT | P2: TGT DUR | Q2: ACT DUR | R2: T SAVING | S2: DELAY REASON STATUS
A3: 1 | B3: MONEYMELA | D3: Issue resolve in Borrower details is not showing in the view details. | F3: COMPLETE | J3: 45372 | K3: 45372 | L3: 45372 | M3: 45373 | N3: =L3 -> 45372 | O3: =N3+P3-1 -> 45372 | P3: =IF(IF(J4="",0,IF(K4="",0,K4-J4))="",0,K4-J4+1) -> 1 | Q3: =IF(L4="",0,IF(M4="",TODAY()-L4,M4-L4+1)) -> 2 | R3: =IF(Q3=0,0,P3-Q3) -> -1
A4: 2 | B4: MONEYMELA | D4: Issue fix of transation id ,Payment mode and deposit bank is not showing in the pending fund report | E4: ISSUE FIX | F4: COMPLETE | J4: 45373 | K4: 45373 | L4: 45373 | M4: 45374 | N4: =IF(L4="",IF(M3="",O3+1,M3+1),L4) -> 45373 | O4: =IF(N4="","",N4+P4-1) -> 45373 | P4: =IF(IF(J5="",0,IF(K5="",0,K5-J5))="",0,K5-J5+1) -> 1 | Q4: =IF(L5="",0,IF(M5="",TODAY()-L5,M5-L5+1)) -> 3 | R4: =IF(Q4=0,0,P4-Q4) -> -2
A5: 3 | B5: MONEYMELA | D5: After profile update when we go to the employee portal for approval in the lender profile some details are not fetched. (EX.Gender and company type) | E5: ISSUE FIX | F5: COMPLETE | J5: 45374 | K5: 45374 | L5: 45374 | M5: 45376 | N5: =IF(L5="",IF(M4="",O4+1,M4+1),L5) -> 45374 | O5: =IF(N5="","",N5+P5-1) -> 45374 | P5: =IF(IF(J5="",0,IF(K5="",0,K5-J5))="",0,K5-J5+1) -> 1 | Q5: =IF(L5="",0,IF(M5="",TODAY()-L5,M5-L5+1)) -> 3 | R5: =IF(Q5=0,0,P5-Q5) -> -2
A6: 4 | B6: MONEYMELA | D6: When we uploaded the document and save without entry some data, its not take submit, but the uploaded document is removed that time. | E6: ISSUE FIX | F6: COMPLETE | J6: 45378 | K6: 45378 | L6: 45378 | M6: 45379 | N6: =IF(L6="",IF(M5="",O5+1,M5+1),L6) -> 45378 | O6: =IF(N6="","",N6+P6-1) -> 45378 | P6: =IF(IF(J6="",0,IF(K6="",0,K6-J6))="",0,K6-J6+1) -> 1 | Q6: =IF(L6="",0,IF(M6="",TODAY()-L6,M6-L6+1)) -> 2 | R6: =IF(Q6=0,0,P6-Q6) -> -1
A7: 5 | B7: MONEYMELA | D7: There should be an admin in moneymela application .to provide access rights to different employees. | E7: IMPROVEMENT | F7: COMPLETE | J7: 45379 | K7: 45380 | L7: 45379 | M7: 45381 | N7: =IF(L7="",IF(M6="",O6+1,M6+1),L7) -> 45379 | O7: =IF(N7="","",N7+P7-1) -> 45380 | P7: =IF(IF(J7="",0,IF(K7="",0,K7-J7))="",0,K7-J7+1) -> 2 | Q7: =IF(L7="",0,IF(M7="",TODAY()-L7,M7-L7+1)) -> 3 | R7: =IF(Q7=0,0,P7-Q7) -> -1
A8: 6 | B8: MONEYMELA | D8: Create a new Page LoanFacility Document | E8: IMPROVEMENT | F8: COMPLETE | J8: 45381 | K8: 45381 | L8: 45381 | M8: 45381 | N8: =IF(L8="",IF(M7="",O7+1,M7+1),L8) -> 45381 | O8: =IF(N8="","",N8+P8-1) -> 45381 | P8: =IF(IF(J8="",0,IF(K8="",0,K8-J8))="",0,K8-J8+1) -> 1 | Q8: =IF(L8="",0,IF(M8="",TODAY()-L8,M8-L8+1)) -> 1 | R8: =IF(Q8=0,0,P8-Q8) -> 0
A9: 7 | B9: MONEYMELA | C9: SANCTION LETTER | D9: Working With Sanction Letter,Create a page for Sanction Letter | E9: IMPROVEMENT | F9: COMPLETE | J9: 45383 | K9: 45386 | L9: 45383 | M9: 45387 | N9: =IF(L9="",IF(M8="",O8+1,M8+1),L9) -> 45383 | O9: =IF(N9="","",N9+P9-1) -> 45386 | P9: =IF(IF(J9="",0,IF(K9="",0,K9-J9))="",0,K9-J9+1) -> 4 | Q9: =IF(L9="",0,IF(M9="",TODAY()-L9,M9-L9+1)) -> 5 | R9: =IF(Q9=0,0,P9-Q9) -> -1
A10: 8 | B10: MONEYMELA | C10: AGREEMENT LETTER | D10: Create New webpage Aggrement Letter | E10: IMPROVEMENT | F10: COMPLETE | J10: 45387 | K10: 45388 | L10: 45387 | M10: 45391 | N10: =IF(L10="",IF(M9="",O9+1,M9+1),L10) -> 45387 | O10: =IF(N10="","",N10+P10-1) -> 45388 | P10: =IF(IF(J10="",0,IF(K10="",0,K10-J10))="",0,K10-J10+1) -> 2 | Q10: =IF(L10="",0,IF(M10="",TODAY()-L10,M10-L10+1)) -> 5 | R10: =IF(Q10=0,0,P10-Q10) -> -3
A11: 9 | B11: MONEYMELA | C11: BANK MANDATE | D11: Create Master For Bank Mandate | E11: IMPROVEMENT | F11: COMPLETE | J11: 45391 | K11: 45391 | L11: 45391 | M11: 45392 | N11: =IF(L11="",IF(M10="",O10+1,M10+1),L11) -> 45391 | O11: =IF(N11="","",N11+P11-1) -> 45391 | P11: =IF(IF(J11="",0,IF(K11="",0,K11-J11))="",0,K11-J11+1) -> 1 | Q11: =IF(L11="",0,IF(M11="",TODAY()-L11,M11-L11+1)) -> 2 | R11: =IF(Q11=0,0,P11-Q11) -> -1
A12: 10 | B12: MONEYMELA | C12: MANAGE BANK | D12: Bank Details Shows and Update in Borrower Profile | E12: IMPROVEMENT | F12: COMPLETE | J12: 45392 | K12: 45393 | L12: 45392 | M12: 45394 | N12: =IF(L12="",IF(M11="",O11+1,M11+1),L12) -> 45392 | O12: =IF(N12="","",N12+P12-1) -> 45393 | P12: =IF(IF(J12="",0,IF(K12="",0,K12-J12))="",0,K12-J12+1) -> 2 | Q12: =IF(L12="",0,IF(M12="",TODAY()-L12,M12-L12+1)) -> 3 | R12: =IF(Q12=0,0,P12-Q12) -> -1
A13: 11 | B13: MONEYMELA | C13: MANAGE BANK | D13: Create Bank Mandate Approval Page | E13: IMPROVEMENT | F13: COMPLETE | J13: 45394 | K13: 45395 | L13: 45394 | M13: 45395 | N13: =IF(L13="",IF(M12="",O12+1,M12+1),L13) -> 45394 | O13: =IF(N13="","",N13+P13-1) -> 45395 | P13: =IF(IF(J13="",0,IF(K13="",0,K13-J13))="",0,K13-J13+1) -> 2 | Q13: =IF(L13="",0,IF(M13="",TODAY()-L13,M13-L13+1)) -> 2 | R13: =IF(Q13=0,0,P13-Q13) -> 0
A14: 12 | B14: MONEYMELA | C14: MANAGE BANK | D14: Bank Mandate Approval details update in Borrower page and reflect it approval management | E14: IMPROVEMENT | F14: COMPLETE | J14: 45395 | K14: 45398 | L14: 45395 | M14: 45399 | N14: =IF(L14="",IF(M13="",O13+1,M13+1),L14) -> 45395 | O14: =IF(N14="","",N14+P14-1) -> 45398 | P14: =IF(IF(J14="",0,IF(K14="",0,K14-J14))="",0,K14-J14+1) -> 4 | Q14: =IF(L14="",0,IF(M14="",TODAY()-L14,M14-L14+1)) -> 5 | R14: =IF(Q14=0,0,P14-Q14) -> -1
A15: 13 | B15: MONEYMELA | C15: MANAGE BANK | D15: Bank Mandate amount from Member will reflect when he/she paid EMI | E15: IMPROVEMENT | F15: COMPLETE | J15: 45399 | K15: 45400 | L15: 45399 | M15: 45404 | N15: =IF(L15="",IF(M14="",O14+1,M14+1),L15) -> 45399 | O15: =IF(N15="","",N15+P15-1) -> 45400 | P15: =IF(IF(J15="",0,IF(K15="",0,K15-J15))="",0,K15-J15+1) -> 2 | Q15: =IF(L15="",0,IF(M15="",TODAY()-L15,M15-L15+1)) -> 6 | R15: =IF(Q15=0,0,P15-Q15) -> -4
A16: 14 | B16: MONEYMELA | C16: MANAGE BANK | D16: Bank Mandate for Employee Portal | E16: IMPROVEMENT | F16: COMPLETE | J16: 45404 | K16: 45404 | L16: 45404 | M16: 45404 | N16: =IF(L16="",IF(M15="",O15+1,M15+1),L16) -> 45404 | O16: =IF(N16="","",N16+P16-1) -> 45404 | P16: =IF(IF(J16="",0,IF(K16="",0,K16-J16))="",0,K16-J16+1) -> 1 | Q16: =IF(L16="",0,IF(M16="",TODAY()-L16,M16-L16+1)) -> 1 | R16: =IF(Q16=0,0,P16-Q16) -> 0
A17: 15 | B17: MONEYMELA | D17: RND with Adhar API | E17: IMPROVEMENT | F17: COMPLETE | J17: 45405 | K17: 45405 | L17: 45405 | M17: 45406 | N17: =IF(L17="",IF(M16="",O16+1,M16+1),L17) -> 45405 | O17: =IF(N17="","",N17+P17-1) -> 45405 | P17: =IF(IF(J17="",0,IF(K17="",0,K17-J17))="",0,K17-J17+1) -> 1 | Q17: =IF(L17="",0,IF(M17="",TODAY()-L17,M17-L17+1)) -> 2 | R17: =IF(Q17=0,0,P17-Q17) -> -1
A18: 16 | B18: MONEYMELA | D18: Authenticate OTP from adhar and get all details RND | E18: IMPROVEMENT | F18: COMPLETE | J18: 45406 | K18: 45406 | L18: 45406 | M18: 45408 | N18: =IF(L18="",IF(M17="",O17+1,M17+1),L18) -> 45406 | O18: =IF(N18="","",N18+P18-1) -> 45406 | P18: =IF(IF(J18="",0,IF(K18="",0,K18-J18))="",0,K18-J18+1) -> 1 | Q18: =IF(L18="",0,IF(M18="",TODAY()-L18,M18-L18+1)) -> 3 | R18: =IF(Q18=0,0,P18-Q18) -> -2
A19: 17 | B19: MONEYMELA | D19: Create table structure and modified code for transaction | E19: IMPROVEMENT | F19: COMPLETE | J19: 45408 | K19: 45409 | L19: 45408 | M19: 45409 | N19: =IF(L19="",IF(M18="",O18+1,M18+1),L19) -> 45408 | O19: =IF(N19="","",N19+P19-1) -> 45409 | P19: =IF(IF(J19="",0,IF(K19="",0,K19-J19))="",0,K19-J19+1) -> 2 | Q19: =IF(L19="",0,IF(M19="",TODAY()-L19,M19-L19+1)) -> 2 | R19: =IF(Q19=0,0,P19-Q19) -> 0
A20: 18 | B20: MONEYMELA | D20: Get Details From PAN NO AND IFSC CODE RND | F20: COMPLETE | J20: 45411 | K20: 45411 | L20: 45411 | M20: 45412 | N20: =IF(L20="",IF(M19="",O19+1,M19+1),L20) -> 45411 | O20: =IF(N20="","",N20+P20-1) -> 45411 | P20: =IF(IF(J20="",0,IF(K20="",0,K20-J20))="",0,K20-J20+1) -> 1 | Q20: =IF(L20="",0,IF(M20="",TODAY()-L20,M20-L20+1)) -> 2 | R20: =IF(Q20=0,0,P20-Q20) -> -1
A21: 19 | B21: MONEYMELA | D21: working in lender data to be inserted for ledger | F21: COMPLETE | J21: 45412 | K21: 45412 | L21: 45412 | M21: 45413 | N21: =IF(L21="",IF(M20="",O20+1,M20+1),L21) -> 45412 | O21: =IF(N21="","",N21+P21-1) -> 45412 | P21: =IF(IF(J21="",0,IF(K21="",0,K21-J21))="",0,K21-J21+1) -> 1 | Q21: =IF(L21="",0,IF(M21="",TODAY()-L21,M21-L21+1)) -> 2 | R21: =IF(Q21=0,0,P21-Q21) -> -1
A22: 20 | B22: MONEYMELA | D22: Approval payment page has some calculation showing wrong . | E22: ISSUE FIX | F22: COMPLETE | J22: 45413 | K22: 45414 | L22: 45413 | N22: =IF(L22="",IF(M21="",O21+1,M21+1),L22) -> 45413 | O22: =IF(N22="","",N22+P22-1) -> 45414 | P22: =IF(IF(J22="",0,IF(K22="",0,K22-J22))="",0,K22-J22+1) -> 2 | Q22: =IF(L22="",0,IF(M22="",TODAY()-L22,M22-L22+1)) -> 35 | R22: =IF(Q22=0,0,P22-Q22) -> -33
A23: 21 | B23: MONEYMELA | D23: In Withdraw page data is store another table and call it at Ledger | E23: IMPROVEMENT | F23: COMPLETE | G23: 45416 | H23: 45416 | I23: 45416 | J23: 45416 | K23: 45416 | L23: 45416 | M23: 45418 | N23: =IF(L23="",IF(M22="",O22+1,M22+1),L23) -> 45416 | O23: =IF(N23="","",N23+P23-1) -> 45416 | P23: =IF(IF(J23="",0,IF(K23="",0,K23-J23))="",0,K23-J23+1) -> 1 | Q23: =IF(L23="",0,IF(M23="",TODAY()-L23,M23-L23+1)) -> 3 | R23: =IF(Q23=0,0,P23-Q23) -> -2
A24: 22 | B24: MONEYMELA | D24: Create a new page for Ledger Report | E24: IMPROVEMENT | F24: COMPLETE | G24: 45418 | H24: 45419 | I24: 45418 | J24: 45418 | K24: 45419 | L24: 45418 | M24: 45419 | N24: =IF(L24="",IF(M23="",O23+1,M23+1),L24) -> 45418 | O24: =IF(N24="","",N24+P24-1) -> 45419 | P24: =IF(IF(J24="",0,IF(K24="",0,K24-J24))="",0,K24-J24+1) -> 2 | Q24: =IF(L24="",0,IF(M24="",TODAY()-L24,M24-L24+1)) -> 2 | R24: =IF(Q24=0,0,P24-Q24) -> 0
A25: 23 | B25: MONEYMELA | D25: Add Loan Page for adding new field and show it data grid. | E25: IMPROVEMENT | F25: COMPLETE | G25: 45420 | H25: 45420 | I25: 45420 | J25: 45420 | K25: 45420 | L25: 45420 | M25: 45421 | N25: =IF(L25="",IF(M24="",O24+1,M24+1),L25) -> 45420 | O25: =IF(N25="","",N25+P25-1) -> 45420 | P25: =IF(IF(J25="",0,IF(K25="",0,K25-J25))="",0,K25-J25+1) -> 1 | Q25: =IF(L25="",0,IF(M25="",TODAY()-L25,M25-L25+1)) -> 2 | R25: =IF(Q25=0,0,P25-Q25) -> -1
A26: 24 | B26: MONEYMELA | D26: Loan Approval Page Shows all Data . | E26: IMPROVEMENT | F26: COMPLETE | J26: 45421 | K26: 45421 | L26: 45421 | M26: 45422 | N26: =IF(L26="",IF(M25="",O25+1,M25+1),L26) -> 45421 | O26: =IF(N26="","",N26+P26-1) -> 45421 | P26: =IF(IF(J26="",0,IF(K26="",0,K26-J26))="",0,K26-J26+1) -> 1 | Q26: =IF(L26="",0,IF(M26="",TODAY()-L26,M26-L26+1)) -> 2 | R26: =IF(Q26=0,0,P26-Q26) -> -1
A27: 25 | B27: MONEYMELA | D27: Correct Data is not coming in Lender Transaction Report | E27: ISSUE FIX | F27: COMPLETE | J27: 45422 | K27: 45422 | L27: 45422 | M27: 45426 | N27: =IF(L27="",IF(M26="",O26+1,M26+1),L27) -> 45422 | O27: =IF(N27="","",N27+P27-1) -> 45422 | P27: =IF(IF(J27="",0,IF(K27="",0,K27-J27))="",0,K27-J27+1) -> 1 | Q27: =IF(L27="",0,IF(M27="",TODAY()-L27,M27-L27+1)) -> 5 | R27: =IF(Q27=0,0,P27-Q27) -> -4
A28: 26 | B28: MONEYMELA | D28: Issue Resolve From Lender Portal | E28: ISSUE FIX | F28: COMPLETE | J28: 45426 | K28: 45426 | L28: 45426 | M28: 45427 | N28: =IF(L28="",IF(M27="",O27+1,M27+1),L28) -> 45426 | O28: =IF(N28="","",N28+P28-1) -> 45426 | P28: =IF(IF(J28="",0,IF(K28="",0,K28-J28))="",0,K28-J28+1) -> 1 | Q28: =IF(L28="",0,IF(M28="",TODAY()-L28,M28-L28+1)) -> 2 | R28: =IF(Q28=0,0,P28-Q28) -> -1
A29: 27 | B29: MONEYMELA | D29: Dynamically CA certificate format to be uploaded. | E29: IMPROVEMENT | F29: COMPLETE | J29: 45427 | K29: 45427 | L29: 45427 | M29: 45428 | N29: =IF(L29="",IF(M28="",O28+1,M28+1),L29) -> 45427 | O29: =IF(N29="","",N29+P29-1) -> 45427 | P29: =IF(IF(J29="",0,IF(K29="",0,K29-J29))="",0,K29-J29+1) -> 1 | Q29: =IF(L29="",0,IF(M29="",TODAY()-L29,M29-L29+1)) -> 2 | R29: =IF(Q29=0,0,P29-Q29) -> -1
A30: 28 | B30: MONEYMELA | D30: Work in investment report section The total principal amt, Principal Received, Loan Status,risk category and remarks details showing wrong. | E30: ISSUE FIX | F30: COMPLETE | J30: 45428 | K30: 45428 | L30: 45428 | M30: 45429 | N30: =IF(L30="",IF(M29="",O29+1,M29+1),L30) -> 45428 | O30: =IF(N30="","",N30+P30-1) -> 45428 | P30: =IF(IF(J30="",0,IF(K30="",0,K30-J30))="",0,K30-J30+1) -> 1 | Q30: =IF(L30="",0,IF(M30="",TODAY()-L30,M30-L30+1)) -> 2 | R30: =IF(Q30=0,0,P30-Q30) -> -1
A31: 29 | B31: MONEYMELA | D31: ISSUE RESOLVE | E31: ISSUE FIX | F31: COMPLETE | J31: 45429 | K31: 45433 | L31: 45429 | M31: 45434 | N31: =IF(L31="",IF(M30="",O30+1,M30+1),L31) -> 45429 | O31: =IF(N31="","",N31+P31-1) -> 45433 | P31: =IF(IF(J31="",0,IF(K31="",0,K31-J31))="",0,K31-J31+1) -> 5 | Q31: =IF(L31="",0,IF(M31="",TODAY()-L31,M31-L31+1)) -> 6 | R31: =IF(Q31=0,0,P31-Q31) -> -1
A32: 30 | B32: MONEYMELA | D32: API Meeting for PAN AND ADHAAR at signzy and RND for integration | E32: OTHER | F32: COMPLETE | J32: 45434 | K32: 45435 | L32: 45434 | M32: 45436 | N32: =IF(L32="",IF(M31="",O31+1,M31+1),L32) -> 45434 | O32: =IF(N32="","",N32+P32-1) -> 45435 | P32: =IF(IF(J32="",0,IF(K32="",0,K32-J32))="",0,K32-J32+1) -> 2 | Q32: =IF(L32="",0,IF(M32="",TODAY()-L32,M32-L32+1)) -> 3 | R32: =IF(Q32=0,0,P32-Q32) -> -1
A33: 31 | B33: MONEYMELA | D33: Video KYC API Meeting From surepass and RND | E33: OTHER | F33: COMPLETE | J33: 45436 | K33: 45437 | L33: 45436 | M33: 45440 | N33: =IF(L33="",IF(M32="",O32+1,M32+1),L33) -> 45436 | O33: =IF(N33="","",N33+P33-1) -> 45437 | P33: =IF(IF(J33="",0,IF(K33="",0,K33-J33))="",0,K33-J33+1) -> 2 | Q33: =IF(L33="",0,IF(M33="",TODAY()-L33,M33-L33+1)) -> 5 | R33: =IF(Q33=0,0,P33-Q33) -> -3
A34: 32 | B34: MONEYMELA | D34: Employee Management Profile Page New Development | E34: IMPROVEMENT | F34: COMPLETE | J34: 45440 | K34: 45441 | L34: 45440 | M34: 45442
A35: 33 | B35: MONEYMELA | D35: Issue Resolve On Lender Management | E35: ISSUE FIX | F35: INPROGRESS | J35: 45442 | K35: 45443 | L35: 45442

Sheet RATNAJEET SINGH
P1: =SUM(P3:P1058) -> 57 | Q1: =SUM(Q3:Q1058) -> 96 | R1: =SUM(R3:R1058) -> -39
A2: SL.NO. | B2: MODULE | C2: SUB MODULE | D2: ACTIVITIES | E2: WORK TYPE | F2: STATUS | G2: APPROVAL | H2: RESTRICTION | I2: NOTIFICATION | J2: TGT ST DATE | K2: TGT END DATE | L2: ACT ST DATE | M2: ACT END DATE | N2: PROB ST DT | O2: PROB END DT | P2: TGT DUR | Q2: ACT DUR | R2: T SAVING | S2: DELAY REASON STATUS
A3: =ROW() - 3 -> 0 | B3: MONEYMELA | D3: Changing the new Databse and table name on new MoneyMelaP2P Application | E3: MODIFICATION | F3: COMPLETE | J3: 45358 | K3: 45358 | L3: 45358 | M3: 45364 | N3: =L3 -> 45358 | O3: =N3+P3-1 -> 45358 | P3: =IF(IF(J3="",0,IF(K3="",0,K3-J3))="",0,K3-J3+1) -> 1 | Q3: =IF(L3="",0,IF(M3="",TODAY()-L3,M3-L3+1)) -> 7 | R3: =IF(Q3=0,0,P3-Q3) -> -6
A4: =ROW() - 3 -> 1 | B4: MONEYMELA | D4: Photo refresh on Lender_UpdateProfile | E4: MODIFICATION | F4: COMPLETE | J4: 45374 | K4: 45376 | L4: 45374 | M4: 45376 | N4: =IF(L4="",IF(M3="",O3+1,M3+1),L4) -> 45374 | O4: =IF(N4="","",N4+P4-1) -> 45376 | P4: =IF(IF(J4="",0,IF(K4="",0,K4-J4))="",0,K4-J4+1) -> 3 | Q4: =IF(L4="",0,IF(M4="",TODAY()-L4,M4-L4+1)) -> 3 | R4: =IF(Q4=0,0,P4-Q4) -> 0
A5: =ROW() - 3 -> 2 | B5: MONEYMELA | D5: Photo remove when page refresh on UpdateProfile2 Page i.e for Borrower Profile Update | E5: MODIFICATION | F5: COMPLETE | J5: 45376 | K5: 45376 | L5: 45376 | M5: 45379 | N5: =IF(L5="",IF(M4="",O4+1,M4+1),L5) -> 45376 | O5: =IF(N5="","",N5+P5-1) -> 45376 | P5: =IF(IF(J5="",0,IF(K5="",0,K5-J5))="",0,K5-J5+1) -> 1 | Q5: =IF(L5="",0,IF(M5="",TODAY()-L5,M5-L5+1)) -> 4 | R5: =IF(Q5=0,0,P5-Q5) -> -3
A6: =ROW() - 3 -> 3 | B6: MONEYMELA | D6: Borrower and Lender Profile Page for replacing the Download button to Icon and change the place of icon | E6: MODIFICATION | F6: COMPLETE | J6: 45378 | K6: 45378 | L6: 45378 | M6: 45380 | N6: =IF(L6="",IF(M5="",O5+1,M5+1),L6) -> 45378 | O6: =IF(N6="","",N6+P6-1) -> 45378 | P6: =IF(IF(J6="",0,IF(K6="",0,K6-J6))="",0,K6-J6+1) -> 1 | Q6: =IF(L6="",0,IF(M6="",TODAY()-L6,M6-L6+1)) -> 3 | R6: =IF(Q6=0,0,P6-Q6) -> -2
A7: =ROW() - 3 -> 4 | B7: MONEYMELA | D7: Employee Management on Admin login on page Admin_EmployeeRegistration | E7: IMPROVEMENT | F7: COMPLETE | J7: 45380 | K7: 45381 | L7: 45381 | M7: 45383 | N7: =IF(L7="",IF(M6="",O6+1,M6+1),L7) -> 45381 | O7: =IF(N7="","",N7+P7-1) -> 45382 | P7: =IF(IF(J7="",0,IF(K7="",0,K7-J7))="",0,K7-J7+1) -> 2 | Q7: =IF(L7="",0,IF(M7="",TODAY()-L7,M7-L7+1)) -> 3 | R7: =IF(Q7=0,0,P7-Q7) -> -1
A8: =ROW() - 3 -> 5 | B8: MONEYMELA | D8: Approval Management Search & Edit | E8: IMPROVEMENT | F8: COMPLETE | J8: 45383 | K8: 45383 | L8: 45383 | M8: 45384 | N8: =IF(L8="",IF(M7="",O7+1,M7+1),L8) -> 45383 | O8: =IF(N8="","",N8+P8-1) -> 45383 | P8: =IF(IF(J8="",0,IF(K8="",0,K8-J8))="",0,K8-J8+1) -> 1 | Q8: =IF(L8="",0,IF(M8="",TODAY()-L8,M8-L8+1)) -> 2 | R8: =IF(Q8=0,0,P8-Q8) -> -1
A9: =ROW() - 3 -> 6 | B9: MONEYMELA | D9: Server Database MODIFICATION | E9: MODIFICATION | F9: COMPLETE | J9: 45384 | K9: 45385 | L9: 45384 | M9: 45386 | N9: =IF(L9="",IF(M8="",O8+1,M8+1),L9) -> 45384 | O9: =IF(N9="","",N9+P9-1) -> 45385 | P9: =IF(IF(J9="",0,IF(K9="",0,K9-J9))="",0,K9-J9+1) -> 2 | Q9: =IF(L9="",0,IF(M9="",TODAY()-L9,M9-L9+1)) -> 3 | R9: =IF(Q9=0,0,P9-Q9) -> -1
A10: =ROW() - 3 -> 7 | B10: MONEYMELA | D10: Database for Admin menu modification | E10: MODIFICATION | F10: COMPLETE | J10: 45386 | K10: 45386 | L10: 45386 | M10: 45386 | N10: =IF(L10="",IF(M9="",O9+1,M9+1),L10) -> 45386 | O10: =IF(N10="","",N10+P10-1) -> 45386 | P10: =IF(IF(J10="",0,IF(K10="",0,K10-J10))="",0,K10-J10+1) -> 1 | Q10: =IF(L10="",0,IF(M10="",TODAY()-L10,M10-L10+1)) -> 1 | R10: =IF(Q10=0,0,P10-Q10) -> 0
A11: =ROW() - 3 -> 8 | B11: MONEYMELA | D11: Employee Profile details after Employee login | E11: IMPROVEMENT | F11: COMPLETE | J11: 45387 | K11: 45388 | L11: 45387 | M11: 45390 | N11: =IF(L11="",IF(M10="",O10+1,M10+1),L11) -> 45387 | O11: =IF(N11="","",N11+P11-1) -> 45388 | P11: =IF(IF(J11="",0,IF(K11="",0,K11-J11))="",0,K11-J11+1) -> 2 | Q11: =IF(L11="",0,IF(M11="",TODAY()-L11,M11-L11+1)) -> 4 | R11: =IF(Q11=0,0,P11-Q11) -> -2
A12: =ROW() - 3 -> 9 | B12: MONEYMELA | D12: Admin EmployeeRegistration Page Validation | E12: IMPROVEMENT | F12: COMPLETE | J12: 45388 | K12: 45390 | L12: 45390 | M12: 45390 | N12: =IF(L12="",IF(M11="",O11+1,M11+1),L12) -> 45390 | O12: =IF(N12="","",N12+P12-1) -> 45392 | P12: =IF(IF(J12="",0,IF(K12="",0,K12-J12))="",0,K12-J12+1) -> 3 | Q12: =IF(L12="",0,IF(M12="",TODAY()-L12,M12-L12+1)) -> 1 | R12: =IF(Q12=0,0,P12-Q12) -> 2
A13: =ROW() - 3 -> 10 | B13: MONEYMELA | D13: Creat new login Page for Admin Login Page SA Login | E13: IMPROVEMENT | F13: COMPLETE | J13: 45390 | K13: 45391 | L13: 45390 | M13: 45391 | N13: =IF(L13="",IF(M12="",O12+1,M12+1),L13) -> 45390 | O13: =IF(N13="","",N13+P13-1) -> 45391 | P13: =IF(IF(J13="",0,IF(K13="",0,K13-J13))="",0,K13-J13+1) -> 2 | Q13: =IF(L13="",0,IF(M13="",TODAY()-L13,M13-L13+1)) -> 2 | R13: =IF(Q13=0,0,P13-Q13) -> 0
A14: =ROW() - 3 -> 11 | B14: MONEYMELA | D14: Creati only for Employee Login portal page i.e Moneymela_Login | E14: IMPROVEMENT | F14: COMPLETE | J14: 45391 | K14: 45392 | L14: 45391 | M14: 45393 | N14: =IF(L14="",IF(M13="",O13+1,M13+1),L14) -> 45391 | O14: =IF(N14="","",N14+P14-1) -> 45392 | P14: =IF(IF(J14="",0,IF(K14="",0,K14-J14))="",0,K14-J14+1) -> 2 | Q14: =IF(L14="",0,IF(M14="",TODAY()-L14,M14-L14+1)) -> 3 | R14: =IF(Q14=0,0,P14-Q14) -> -1
A15: 13 | B15: MONEYMELA | D15: Validation when he click Update on Profile Page for Borrower portal after approve from Admin . | E15: MODIFICATION | F15: COMPLETE | J15: 45393 | K15: 45393 | L15: 45393 | M15: 45394 | N15: =IF(L15="",IF(M14="",O14+1,M14+1),L15) -> 45393 | O15: =IF(N15="","",N15+P15-1) -> 45393 | P15: =IF(IF(J15="",0,IF(K15="",0,K15-J15))="",0,K15-J15+1) -> 1 | Q15: =IF(L15="",0,IF(M15="",TODAY()-L15,M15-L15+1)) -> 2 | R15: =IF(Q15=0,0,P15-Q15) -> -1
A16: 14 | B16: MONEYMELA | D16: Lender_UpdateProfile validation | E16: IMPROVEMENT | F16: COMPLETE | J16: 45394 | K16: 45394 | L16: 45394 | M16: 45395 | N16: =IF(L16="",IF(M15="",O15+1,M15+1),L16) -> 45394 | O16: =IF(N16="","",N16+P16-1) -> 45394 | P16: =IF(IF(J16="",0,IF(K16="",0,K16-J16))="",0,K16-J16+1) -> 1 | Q16: =IF(L16="",0,IF(M16="",TODAY()-L16,M16-L16+1)) -> 2 | R16: =IF(Q16=0,0,P16-Q16) -> -1
A17: 15 | B17: MONEYMELA | D17: Working on Lender_Profile page Validation | F17: COMPLETE | J17: 45397 | K17: 45397 | L17: 45398 | M17: 45398 | N17: =IF(L17="",IF(M16="",O16+1,M16+1),L17) -> 45398 | O17: =IF(N17="","",N17+P17-1) -> 45398 | P17: =IF(IF(J17="",0,IF(K17="",0,K17-J17))="",0,K17-J17+1) -> 1 | Q17: =IF(L17="",0,IF(M17="",TODAY()-L17,M17-L17+1)) -> 1 | R17: =IF(Q17=0,0,P17-Q17) -> 0
A18: 16 | B18: MONEYMELA | D18: Issue fixing on UpdateProfile2 on Borrower Profile | E18: ISSUE FIX | F18: COMPLETE | J18: 45398 | K18: 45398 | L18: 45398 | M18: 45399 | N18: =IF(L18="",IF(M17="",O17+1,M17+1),L18) -> 45398 | O18: =IF(N18="","",N18+P18-1) -> 45398 | P18: =IF(IF(J18="",0,IF(K18="",0,K18-J18))="",0,K18-J18+1) -> 1 | Q18: =IF(L18="",0,IF(M18="",TODAY()-L18,M18-L18+1)) -> 2 | R18: =IF(Q18=0,0,P18-Q18) -> -1
A19: 17 | B19: MONEYMELA | D19: Issue fixing on Admin Portal Loan Management | E19: ISSUE FIX | F19: COMPLETE | J19: 45399 | K19: 45400 | L19: 45399 | M19: 45401 | N19: =IF(L19="",IF(M18="",O18+1,M18+1),L19) -> 45399 | O19: =IF(N19="","",N19+P19-1) -> 45400 | P19: =IF(IF(J19="",0,IF(K19="",0,K19-J19))="",0,K19-J19+1) -> 2 | Q19: =IF(L19="",0,IF(M19="",TODAY()-L19,M19-L19+1)) -> 3 | R19: =IF(Q19=0,0,P19-Q19) -> -1
A20: 18 | B20: MONEYMELA | D20: User right for Bank Mandate | E20: IMPROVEMENT | F20: COMPLETE | J20: 45401 | K20: 45401 | L20: 45401 | M20: 45404 | N20: =IF(L20="",IF(M19="",O19+1,M19+1),L20) -> 45401 | O20: =IF(N20="","",N20+P20-1) -> 45401 | P20: =IF(IF(J20="",0,IF(K20="",0,K20-J20))="",0,K20-J20+1) -> 1 | Q20: =IF(L20="",0,IF(M20="",TODAY()-L20,M20-L20+1)) -> 4 | R20: =IF(Q20=0,0,P20-Q20) -> -3
A21: 19 | B21: MONEYMELA | D21: Bank Mandate for Lender Portal | E21: IMPROVEMENT | F21: COMPLETE | J21: 45402 | K21: 45405 | L21: 45402 | M21: 45406 | N21: =IF(L21="",IF(M20="",O20+1,M20+1),L21) -> 45402 | O21: =IF(N21="","",N21+P21-1) -> 45405 | P21: =IF(IF(J21="",0,IF(K21="",0,K21-J21))="",0,K21-J21+1) -> 4 | Q21: =IF(L21="",0,IF(M21="",TODAY()-L21,M21-L21+1)) -> 5 | R21: =IF(Q21=0,0,P21-Q21) -> -1
A22: 20 | B22: MONEYMELA | D22: Issue resolve on Admin_Loan_Registration page on Employee Portal | E22: ISSUE FIX | F22: COMPLETE | J22: 45406 | K22: 45406 | L22: 45406 | M22: 45407 | N22: =IF(L22="",IF(M21="",O21+1,M21+1),L22) -> 45406 | O22: =IF(N22="","",N22+P22-1) -> 45406 | P22: =IF(IF(J22="",0,IF(K22="",0,K22-J22))="",0,K22-J22+1) -> 1 | Q22: =IF(L22="",0,IF(M22="",TODAY()-L22,M22-L22+1)) -> 2 | R22: =IF(Q22=0,0,P22-Q22) -> -1
A23: 21 | B23: MONEYMELA | D23: Issue fixing on Make Payment on Lender portal | E23: ISSUE FIX | F23: COMPLETE | J23: 45407 | K23: 45407 | L23: 45408 | M23: 45408 | N23: =IF(L23="",IF(M22="",O22+1,M22+1),L23) -> 45408 | O23: =IF(N23="","",N23+P23-1) -> 45408 | P23: =IF(IF(J23="",0,IF(K23="",0,K23-J23))="",0,K23-J23+1) -> 1 | Q23: =IF(L23="",0,IF(M23="",TODAY()-L23,M23-L23+1)) -> 1 | R23: =IF(Q23=0,0,P23-Q23) -> 0
A24: 22 | B24: MONEYMELA | D24: Working for photo issue Bank Statement PAN card issue on Admin/Approval Management/ Loan approval | E24: ISSUE FIX | F24: COMPLETE | J24: 45408 | K24: 45408 | L24: 45408 | M24: 45408 | N24: =IF(L24="",IF(M23="",O23+1,M23+1),L24) -> 45408 | O24: =IF(N24="","",N24+P24-1) -> 45408 | P24: =IF(IF(J24="",0,IF(K24="",0,K24-J24))="",0,K24-J24+1) -> 1 | Q24: =IF(L24="",0,IF(M24="",TODAY()-L24,M24-L24+1)) -> 1 | R24: =IF(Q24=0,0,P24-Q24) -> 0
A25: 23 | B25: MONEYMELA | D25: Issue resolving on Pending Form report on Support Management Admin Portal | E25: ISSUE FIX | F25: COMPLETE | J25: 45408 | K25: 45408 | L25: 45408 | M25: 45409 | N25: =IF(L25="",IF(M24="",O24+1,M24+1),L25) -> 45408 | O25: =IF(N25="","",N25+P25-1) -> 45408 | P25: =IF(IF(J25="",0,IF(K25="",0,K25-J25))="",0,K25-J25+1) -> 1 | Q25: =IF(L25="",0,IF(M25="",TODAY()-L25,M25-L25+1)) -> 2 | R25: =IF(Q25=0,0,P25-Q25) -> -1
A26: 24 | B26: MONEYMELA | D26: Find out the path for uploaded photo for entire solution | E26: IMPROVEMENT | F26: COMPLETE | J26: 45411 | K26: 45411 | L26: 45411 | M26: 45412 | N26: =IF(L26="",IF(M25="",O25+1,M25+1),L26) -> 45411 | O26: =IF(N26="","",N26+P26-1) -> 45411 | P26: =IF(IF(J26="",0,IF(K26="",0,K26-J26))="",0,K26-J26+1) -> 1 | Q26: =IF(L26="",0,IF(M26="",TODAY()-L26,M26-L26+1)) -> 2 | R26: =IF(Q26=0,0,P26-Q26) -> -1
A27: 25 | B27: MONEYMELA | D27: Issue fixing resolve from Website | E27: IMPROVEMENT | F27: COMPLETE | J27: 45413 | K27: 45414 | L27: 45413 | M27: 45416 | N27: =IF(L27="",IF(M26="",O26+1,M26+1),L27) -> 45413 | O27: =IF(N27="","",N27+P27-1) -> 45414 | P27: =IF(IF(J27="",0,IF(K27="",0,K27-J27))="",0,K27-J27+1) -> 2 | Q27: =IF(L27="",0,IF(M27="",TODAY()-L27,M27-L27+1)) -> 4 | R27: =IF(Q27=0,0,P27-Q27) -> -2
A28: 26 | B28: MONEYMELA | D28: Update_Profile2 page on Borrower portal for modifying to save the image | E28: IMPROVEMENT | F28: COMPLETE | J28: 45420 | K28: 45421 | L28: 45420 | M28: 45422 | N28: =IF(L28="",IF(M27="",O27+1,M27+1),L28) -> 45420 | O28: =IF(N28="","",N28+P28-1) -> 45421 | P28: =IF(IF(J28="",0,IF(K28="",0,K28-J28))="",0,K28-J28+1) -> 2 | Q28: =IF(L28="",0,IF(M28="",TODAY()-L28,M28-L28+1)) -> 3 | R28: =IF(Q28=0,0,P28-Q28) -> -1
A29: 27 | B29: MONEYMELA | D29: Issue fixing website (As per Arpita) | E29: ISSUE FIX | F29: COMPLETE | J29: 45422 | K29: 45422 | L29: 45422 | M29: 45426 | N29: =IF(L29="",IF(M28="",O28+1,M28+1),L29) -> 45422 | O29: =IF(N29="","",N29+P29-1) -> 45422 | P29: =IF(IF(J29="",0,IF(K29="",0,K29-J29))="",0,K29-J29+1) -> 1 | Q29: =IF(L29="",0,IF(M29="",TODAY()-L29,M29-L29+1)) -> 5 | R29: =IF(Q29=0,0,P29-Q29) -> -4
... A36: 34 | B36: MONEYMELA | D36: Issue fixing on Borrower portal & Working on Modifying Bank Account Details adding some field as per required in Borrower Portal | E36: ISSUE FIX | F36: COMPLETE | J36: 45435 | K36: 45439 | L36: 45435 | M36: 45440 | N36: =IF(L36="",IF(M35="",O35+1,M35+1),L36) -> 45435 | O36: =IF(N36="","",N36+P36-1) -> 45439 | P36: =IF(IF(J36="",0,IF(K36="",0,K36-J36))="",0,K36-J36+1) -> 5 | Q36: =IF(L36="",0,IF(M36="",TODAY()-L36,M36-L36+1)) -> 6 | R36: =IF(Q36=0,0,P36-Q36) -> -1
A37: 35 | B37: MONEYMELA | D37: Working on MemberRegisteration and InvestorRegisteration search & Edit on Admin portal | E37: IMPROVEMENT | F37: COMPLETE | J37: 45440 | K37: 45440 | L37: 45440 | M37: 45442
A38: 36 | B38: MONEYMELA | D38: Issue fixing in Admin_EmployeeRegistration page | E38: ISSUE FIX | F38: COMPLETE | J38: 45441 | K38: 45441 | L38: 45442 | M38: 45442
A39: 37 | B39: MONEYMELA | D39: Modifying in Member Registeration for dropdown value at Admin portal | F39: COMPLETE | J39: 45442 | K39: 45442 | L39: 45443 | M39: 45443
A40: 38 | B40: MONEYMELA | D40: Lender, Borrower portal for modifying the dropdown details and checking validation | E40: IMPROVEMENT | F40: COMPLETE | J40: 45443 | K40: 45443 | L40: 45443 | M40: 45443
A41: 39 | B41: MONEYMELA | D41: Issue fixing In Employee Registration time Aadhar number field. Also in upload document field age proof name and in the drop down PAN Card | E41: ISSUE FIX | F41: INPROGRESS | J41: 45444 | K41: 45444 | L41: 45444

Sheet CHETAN
P1: =SUM(P3:P1009) -> 264 | Q1: =SUM(Q3:Q1009) -> 500 | R1: =SUM(R3:R1009) -> -236
A2: SL.NO. | B2: MODULE | C2: SUB MODULE | D2: ACTIVITIES | E2: WORK TYPE | F2: STATUS | G2: APPROVAL | H2: RESTRICTION | I2: NOTIFICATION | J2: TGT ST DATE | K2: TGT END DATE | L2: ACT ST DATE | M2: ACT END DATE | N2: PROB ST DT | O2: PROB END DT | P2: TGT DUR | Q2: ACT DUR | R2: T SAVING | S2: DELAY REASON STATUS
A3: =ROW() - ROW($A$30) + 28 -> 1 | B3: MASTER DATA | C3: LOCAL SUPPLIER(GENERAL) | D3: Manage Local Supplier Listing Page As Per 2Nd Phase Wth Dynamic Approval | E3: 2ND STAGE IMPLEMENTATION | F3: LIVE | J3: 45072 | K3: 45075 | L3: 45072 | M3: 45136 | N3: =L3 -> 45072 | O3: =N3+P3-1 -> 45075 | P3: =IF(IF(J3="",0,IF(K3="",0,K3-J3))="",0,K3-J3+1) -> 4 | Q3: =IF(L3="",0,IF(M3="",TODAY()-L3,M3-L3+1)) -> 65 | R3: =IF(Q3=0,0,P3-Q3) -> -61
A4: =ROW() - ROW($A$30) + 28 -> 2 | B4: NEW | C4: Format Control Module | D4: Format Control Module | E4: FORM | F4: TESTING | J4: 45100 | K4: 45135 | L4: 45100 | M4: 45135 | N4: =IF(L4="",IF(M3="",O3+1,M3+1),L4) -> 45100 | O4: =+N4+P4-1 -> 45135 | P4: =IF(IF(J4="",0,IF(K4="",0,K4-J4))="",0,K4-J4+1) -> 36 | Q4: =IF(L4="",0,IF(M4="",TODAY()-L4,M4-L4+1)) -> 36 | R4: =IF(Q4=0,0,P4-Q4) -> 0 | S4: IT'S IN LIVE SERVER AND ASSIGNED MANAGMENT FOR TESTING
A5: =ROW() - ROW($A$30) + 28 -> 3 | B5: MASTER DATA | C5: LOCAL SUPPLIER(GENERAL) | D5: Error and Issue fix in mange local supplier,Validation in add local supplier,mange local supplier process guide documentation | E5: ISSUE | F5: LIVE | J5: 45135 | K5: 45163 | L5: 45135 | M5: 45168 | N5: =IF(L5="",IF(M4="",O4+1,M4+1),L5) -> 45135 | O5: =+N5+P5-1 -> 45163 | P5: =IF(IF(J5="",0,IF(K5="",0,K5-J5))="",0,K5-J5+1) -> 29 | Q5: =IF(L5="",0,IF(M5="",TODAY()-L5,M5-L5+1)) -> 34 | R5: =IF(Q5=0,0,P5-Q5) -> -5
A6: =ROW() - ROW($A$30) + 28 -> 4 | B6: MASTER DATA | C6: MAMAGE LOCATION(PROJECT) | D6: State, District, Block, Gramapanchayat | E6: 2ND STAGE IMPLEMENTATION | F6: LIVE | J6: 45167 | K6: 45187 | L6: 45168 | M6: 45215 | N6: =IF(L6="",IF(M5="",O5+1,M5+1),L6) -> 45168 | O6: =+N6+P6-1 -> 45188 | P6: =IF(IF(J6="",0,IF(K6="",0,K6-J6))="",0,K6-J6+1) -> 21 | Q6: =IF(L6="",0,IF(M6="",TODAY()-L6,M6-L6+1)) -> 48 | R6: =IF(Q6=0,0,P6-Q6) -> -27
A7: =ROW() - ROW($A$30) + 28 -> 5 | B7: MASTER DATA | C7: CATEGORY AND SUB CATEGORY(PROJECT) | D7: Manage Category and sub category new design and dynamic approval. | E7: 2ND STAGE IMPLEMENTATION | F7: LIVE | J7: 45194 | K7: 45202 | L7: 45195 | M7: 45205 | N7: =IF(L7="",IF(M6="",O6+1,M6+1),L7) -> 45195 | O7: =+N7+P7-1 -> 45203 | P7: =IF(IF(J7="",0,IF(K7="",0,K7-J7))="",0,K7-J7+1) -> 9 | Q7: =IF(L7="",0,IF(M7="",TODAY()-L7,M7-L7+1)) -> 11 | R7: =IF(Q7=0,0,P7-Q7) -> -2
A8: =ROW() - ROW($A$30) + 28 -> 6 | B8: MASTER DATA | C8: MANAGE GROUP AND SUB GROUP | D8: Manage group and sub group new design and dynamic approval. | E8: 2ND STAGE IMPLEMENTATION | F8: LIVE | J8: 45202 | K8: 45209 | L8: 45205 | M8: 45209 | N8: =IF(L8="",IF(M7="",O7+1,M7+1),L8) -> 45205 | O8: =+N8+P8-1 -> 45212 | P8: =IF(IF(J8="",0,IF(K8="",0,K8-J8))="",0,K8-J8+1) -> 8 | Q8: =IF(L8="",0,IF(M8="",TODAY()-L8,M8-L8+1)) -> 5 | R8: =IF(Q8=0,0,P8-Q8) -> 3
A9: =ROW() - ROW($A$30) + 28 -> 7 | B9: MASTER DATA | C9: MANAGE MATERIAL | D9: Manage Material in Manage Project part | E9: 2ND STAGE IMPLEMENTATION | F9: LIVE | J9: 45209 | K9: 45212 | L9: 45209 | M9: 45215 | N9: =IF(L9="",IF(M8="",O8+1,M8+1),L9) -> 45209 | O9: =+N9+P9-1 -> 45212 | P9: =IF(IF(J9="",0,IF(K9="",0,K9-J9))="",0,K9-J9+1) -> 4 | Q9: =IF(L9="",0,IF(M9="",TODAY()-L9,M9-L9+1)) -> 7 | R9: =IF(Q9=0,0,P9-Q9) -> -3
A10: =ROW() - ROW($A$30) + 28 -> 8 | B10: FINANCE | C10: MAMAGE LOCATION(PROJECT) | D10: Download Excel functionality in Manage Head of Grouping in Finance module.Filtration and PhP Pagination and Sorting in Manage location | F10: LIVE | J10: 45215 | K10: 45229 | L10: 45215 | M10: 45232 | N10: =IF(L10="",IF(M9="",O9+1,M9+1),L10) -> 45215 | O10: =+N10+P10-1 -> 45229 | P10: =IF(IF(J10="",0,IF(K10="",0,K10-J10))="",0,K10-J10+1) -> 15 | Q10: =IF(L10="",0,IF(M10="",TODAY()-L10,M10-L10+1)) -> 18 | R10: =IF(Q10=0,0,P10-Q10) -> -3
A11: =ROW() - ROW($A$30) + 28 -> 9 | B11: MASTER DATA | C11: FINANCE | D11: Manage Bank Account dynamic approval ,filtration and php pagination and dynamic approval | E11: 2ND STAGE IMPLEMENTATION | F11: INCOMPLETE | J11: 45230 | K11: 45238 | L11: 45227 | M11: 45238 | N11: =IF(L11="",IF(M10="",O10+1,M10+1),L11) -> 45227 | O11: =+N11+P11-1 -> 45235 | P11: =IF(IF(J11="",0,IF(K11="",0,K11-J11))="",0,K11-J11+1) -> 9 | Q11: =IF(L11="",0,IF(M11="",TODAY()-L11,M11-L11+1)) -> 12 | R11: =IF(Q11=0,0,P11-Q11) -> -3 | S11: TEAM LEAD WILL CHECK THE REPORT AND SHE WILL ASSIGN IT FOR TESTING
A12: =ROW() - ROW($A$30) + 28 -> 10 | B12: MASTER DATA | C12: CATEGORY AND SUB CATEGORY,GROUP SUB GROUP | D12: Php pagination and filtration in mange category, mange sub category and issue solve.Pagination and filtration in mange group, mange sub sub_group and mange material. | E12: ISSUE | F12: LIVE | J12: 45238 | K12: 45240 | L12: 45238 | M12: 45250 | N12: =IF(L12="",IF(M11="",O11+1,M11+1),L12) -> 45238 | O12: =+N12+P12-1 -> 45240 | P12: =IF(IF(J12="",0,IF(K12="",0,K12-J12))="",0,K12-J12+1) -> 3 | Q12: =IF(L12="",0,IF(M12="",TODAY()-L12,M12-L12+1)) -> 13 | R12: =IF(Q12=0,0,P12-Q12) -> -10 | S12: TEAM LEAD WILL CHECK THE REPORT AND SHE WILL ASSIGN IT FOR TESTING
A13: =ROW() - ROW($A$30) + 28 -> 11 | B13: EXPENSE | C13: ALL PAYMENT REQUEST | D13: Page speed functionality in expense module (expense report -> all payment request) | E13: PAGE SPEED FUNCTIONALITY | F13: LIVE | J13: 45250 | K13: 45255 | L13: 45250 | M13: 45259 | N13: =IF(L13="",IF(M12="",O12+1,M12+1),L13) -> 45250 | O13: =+N13+P13-1 -> 45255 | P13: =IF(IF(J13="",0,IF(K13="",0,K13-J13))="",0,K13-J13+1) -> 6 | Q13: =IF(L13="",0,IF(M13="",TODAY()-L13,M13-L13+1)) -> 10 | R13: =IF(Q13=0,0,P13-Q13) -> -4 | S13: IT'S DELAY DUE TO DEV SERVER ISSUE
A14: =ROW() - ROW($A$30) + 28 -> 12 | B14: EXPENSE | C14: REPORT | D14: New design, speed customization in journal report | E14: PAGE SPEED FUNCTIONALITY | F14: LIVE | J14: 45259 | K14: 45262 | L14: 45266 | M14: 45266 | N14: =IF(L14="",IF(M13="",O13+1,M13+1),L14) -> 45266 | O14: =+N14+P14-1 -> 45269 | P14: =IF(IF(J14="",0,IF(K14="",0,K14-J14))="",0,K14-J14+1) -> 4 | Q14: =IF(L14="",0,IF(M14="",TODAY()-L14,M14-L14+1)) -> 1 | R14: =IF(Q14=0,0,P14-Q14) -> 3 | S14: TEAM LEAD WILL CHECK THE REPORT AND SHE WILL ASSIGN IT FOR TESTING
A15: =ROW() - ROW($A$30) + 28 -> 13 | B15: SALES | D15: Review of documentation of Sales CRM,Database , login and registration set up of sales CRM in local | E15: OTHER | F15: COMPLETE | J15: 45266 | K15: 45272 | L15: 45266 | M15: 45272 | N15: =IF(L15="",IF(M14="",O14+1,M14+1),L15) -> 45266 | O15: =+N15+P15-1 -> 45272 | P15: =IF(IF(J15="",0,IF(K15="",0,K15-J15))="",0,K15-J15+1) -> 7 | Q15: =IF(L15="",0,IF(M15="",TODAY()-L15,M15-L15+1)) -> 7 | R15: =IF(Q15=0,0,P15-Q15) -> 0 | S15: TEAM LEAD WILL CHECK THE REPORT AND SHE WILL ASSIGN IT FOR TESTING
A16: =ROW() - ROW($A$30) + 28 -> 14 | B16: SALES | C16: COUNTRY | D16: Adding country of location part in sale crm | E16: IMPROVEMENT | F16: COMPLETE | J16: 45272 | K16: 45273 | L16: 45272 | M16: 45274 | N16: =IF(L16="",IF(M15="",O15+1,M15+1),L16) -> 45272 | O16: =+N16+P16-1 -> 45273 | P16: =IF(IF(J16="",0,IF(K16="",0,K16-J16))="",0,K16-J16+1) -> 2 | Q16: =IF(L16="",0,IF(M16="",TODAY()-L16,M16-L16+1)) -> 3 | R16: =IF(Q16=0,0,P16-Q16) -> -1
A17: =ROW() - ROW($A$30) + 28 -> 15 | B17: SALES | C17: DISTRICT | D17: Adding district of location part in sale crm | E17: IMPROVEMENT | F17: COMPLETE | G17: 45274 | J17: 45274 | K17: 45275 | L17: 45274 | M17: 45276 | N17: =IF(L17="",IF(M16="",O16+1,M16+1),L17) -> 45274 | O17: =+N17+P17-1 -> 45275 | P17: =IF(IF(J17="",0,IF(K17="",0,K17-J17))="",0,K17-J17+1) -> 2 | Q17: =IF(L17="",0,IF(M17="",TODAY()-L17,M17-L17+1)) -> 3 | R17: =IF(Q17=0,0,P17-Q17) -> -1
A18: =ROW() - ROW($A$30) + 28 -> 16 | B18: SALES | D18: Remodification of Database of Sales CRM and Form Design. | E18: MODIFICATION | F18: COMPLETE | J18: 45285 | K18: 45286 | L18: 45287 | M18: 45287 | N18: =IF(L18="",IF(M17="",O17+1,M17+1),L18) -> 45287 | O18: =+N18+P18-1 -> 45288 | P18: =IF(IF(J18="",0,IF(K18="",0,K18-J18))="",0,K18-J18+1) -> 2 | Q18: =IF(L18="",0,IF(M18="",TODAY()-L18,M18-L18+1)) -> 1 | R18: =IF(Q18=0,0,P18-Q18) -> 1
A19: =ROW() - ROW($A$30) + 28 -> 17 | B19: SALES | C19: MANAGE BANK | D19: create bank master and bank account details form in sales crm | E19: IMPROVEMENT | F19: COMPLETE | J19: 45286 | K19: 45287 | L19: 45287 | M19: 45288 | N19: =IF(L19="",IF(M18="",O18+1,M18+1),L19) -> 45287 | O19: =+N19+P19-1 -> 45288 | P19: =IF(IF(J19="",0,IF(K19="",0,K19-J19))="",0,K19-J19+1) -> 2 | Q19: =IF(L19="",0,IF(M19="",TODAY()-L19,M19-L19+1)) -> 2 | R19: =IF(Q19=0,0,P19-Q19) -> 0
A20: =ROW() - ROW($A$30) + 28 -> 18 | B20: SALES | C20: TERM/PAYMENT TERM | D20: Term Master and Payment Term creation in sales crm | E20: IMPROVEMENT | F20: COMPLETE | J20: 45288 | K20: 45289 | L20: 45288 | M20: 45288 | N20: =IF(L20="",IF(M19="",O19+1,M19+1),L20) -> 45288 | O20: =+N20+P20-1 -> 45289 | P20: =IF(IF(J20="",0,IF(K20="",0,K20-J20))="",0,K20-J20+1) -> 2 | Q20: =IF(L20="",0,IF(M20="",TODAY()-L20,M20-L20+1)) -> 1 | R20: =IF(Q20=0,0,P20-Q20) -> 1
A21: =ROW() - ROW($A$30) + 28 -> 19 | B21: SALES | C21: TAX | D21: Tax master creation in sales crm | E21: IMPROVEMENT | F21: COMPLETE | J21: 45288 | K21: 45289 | L21: 45288 | M21: 45289 | N21: =IF(L21="",IF(M20="",O20+1,M20+1),L21) -> 45288 | O21: =+N21+P21-1 -> 45289 | P21: =IF(IF(J21="",0,IF(K21="",0,K21-J21))="",0,K21-J21+1) -> 2 | Q21: =IF(L21="",0,IF(M21="",TODAY()-L21,M21-L21+1)) -> 2 | R21: =IF(Q21=0,0,P21-Q21) -> 0
A22: =ROW() - ROW($A$30) + 28 -> 20 | B22: SALES | C22: LEAD STAGE /LEAD STATUS | D22: Lead Stage and Lead status master creation in sales CRM | E22: IMPROVEMENT | F22: COMPLETE | J22: 45289 | K22: 45290 | L22: 45289 | M22: 45294 | N22: =IF(L22="",IF(M21="",O21+1,M21+1),L22) -> 45289 | O22: =+N22+P22-1 -> 45290 | P22: =IF(IF(J22="",0,IF(K22="",0,K22-J22))="",0,K22-J22+1) -> 2 | Q22: =IF(L22="",0,IF(M22="",TODAY()-L22,M22-L22+1)) -> 6 | R22: =IF(Q22=0,0,P22-Q22) -> -4
A23: =ROW() - ROW($A$30) + 28 -> 21 | B23: SALES | C23: PRODUCT AND SERVICE | D23: Product/Service master creation in sales crm | E23: IMPROVEMENT | F23: COMPLETE | J23: 45292 | K23: 45293 | L23: 45294 | M23: 45294 | N23: =IF(L23="",IF(M22="",O22+1,M22+1),L23) -> 45294 | O23: =+N23+P23-1 -> 45295 | P23: =IF(IF(J23="",0,IF(K23="",0,K23-J23))="",0,K23-J23+1) -> 2 | Q23: =IF(L23="",0,IF(M23="",TODAY()-L23,M23-L23+1)) -> 1 | R23: =IF(Q23=0,0,P23-Q23) -> 1
A24: =ROW() - ROW($A$30) + 28 -> 22 | B24: SALES | D24: modification work of branch master and employee master in sales CRM | E24: MODIFICATION | F24: COMPLETE | J24: 45294 | K24: 45295 | L24: 45294 | M24: 45300 | N24: =IF(L24="",IF(M23="",O23+1,M23+1),L24) -> 45294 | O24: =+N24+P24-1 -> 45295 | P24: =IF(IF(J24="",0,IF(K24="",0,K24-J24))="",0,K24-J24+1) -> 2 | Q24: =IF(L24="",0,IF(M24="",TODAY()-L24,M24-L24+1)) -> 7 | R24: =IF(Q24=0,0,P24-Q24) -> -5
A25: =ROW() - ROW($A$30) + 28 -> 23 | B25: SALES | C25: ENQUIRY BUCKET | D25: Enquiry Bucket Master Sales CRM | E25: IMPROVEMENT | F25: COMPLETE | J25: 45299 | K25: 45303 | L25: 45300 | M25: 45315 | N25: =IF(L25="",IF(M24="",O24+1,M24+1),L25) -> 45300 | O25: =+N25+P25-1 -> 45304 | P25: =IF(IF(J25="",0,IF(K25="",0,K25-J25))="",0,K25-J25+1) -> 5 | Q25: =IF(L25="",0,IF(M25="",TODAY()-L25,M25-L25+1)) -> 16 | R25: =IF(Q25=0,0,P25-Q25) -> -11
A26: =ROW() - ROW($A$30) + 28 -> 24 | B26: SALES | D26: Sales CRM listing page's Enquiry bucket includes the implementation of the Pending To Assign tab, while the view page is undergoing follow-up functionality implementation. | E26: OTHER | F26: COMPLETE | J26: 45309 | K26: 45314 | L26: 45315 | M26: 45321 | N26: =IF(L26="",IF(M25="",O25+1,M25+1),L26) -> 45315 | O26: =+N26+P26-1 -> 45320 | P26: =IF(IF(J26="",0,IF(K26="",0,K26-J26))="",0,K26-J26+1) -> 6 | Q26: =IF(L26="",0,IF(M26="",TODAY()-L26,M26-L26+1)) -> 7 | R26: =IF(Q26=0,0,P26-Q26) -> -1
A27: =ROW() - ROW($A$30) + 28 -> 25 | B27: SALES | D27: Rectification the issue in enquiry bucket and follow up | E27: TESTING ISSUE | F27: COMPLETE | J27: 45315 | K27: 45318 | L27: 45321 | M27: 45323 | N27: =IF(L27="",IF(M26="",O26+1,M26+1),L27) -> 45321 | O27: =+N27+P27-1 -> 45324 | P27: =IF(IF(J27="",0,IF(K27="",0,K27-J27))="",0,K27-J27+1) -> 4 | Q27: =IF(L27="",0,IF(M27="",TODAY()-L27,M27-L27+1)) -> 3 | R27: =IF(Q27=0,0,P27-Q27) -> 1
A28: =ROW() - ROW($A$30) + 28 -> 26 | B28: SALES | C28: MY TODAYS FOLLOW UP | D28: My Todays Follow up in sales crm | E28: IMPROVEMENT | F28: COMPLETE | J28: 45322 | K28: 45324 | L28: 45323 | M28: 45329 | N28: =IF(L28="",IF(M27="",O27+1,M27+1),L28) -> 45323 | O28: =+N28+P28-1 -> 45325 | P28: =IF(IF(J28="",0,IF(K28="",0,K28-J28))="",0,K28-J28+1) -> 3 | Q28: =IF(L28="",0,IF(M28="",TODAY()-L28,M28-L28+1)) -> 7 | R28: =IF(Q28=0,0,P28-Q28) -> -4
A29: =ROW() - ROW($A$30) + 28 -> 27 | B29: SALES | C29: UPCOMING FOLLOW UP | D29: Upcoming Follow up in sale CRM | E29: IMPROVEMENT | F29: COMPLETE | J29: 45328 | K29: 45329 | L29: 45329 | M29: 45329 | N29: =IF(L29="",IF(M28="",O28+1,M28+1),L29) -> 45329 | O29: =+N29+P29-1 -> 45330 | P29: =IF(IF(J29="",0,IF(K29="",0,K29-J29))="",0,K29-J29+1) -> 2 | Q29: =IF(L29="",0,IF(M29="",TODAY()-L29,M29-L29+1)) -> 1 | R29: =IF(Q29=0,0,P29-Q29) -> 1
A30: =ROW() - ROW($A$30) + 28 -> 28 | B30: SALES | D30: Testing in Location Masters of sales CRM | E30: TESTING ISSUE | F30: COMPLETE | J30: 45329 | K30: 45329 | L30: 45329 | M30: 45330 | N30: =IF(L30="",IF(M29="",O29+1,M29+1),L30) -> 45329 | O30: =+N30+P30-1 -> 45329 | P30: =IF(IF(J30="",0,IF(K30="",0,K30-J30))="",0,K30-J30+1) -> 1 | Q30: =IF(L30="",0,IF(M30="",TODAY()-L30,M30-L30+1)) -> 2 | R30: =IF(Q30=0,0,P30-Q30) -> -1
A31: =ROW() - ROW($A$30) + 28 -> 29 | B31: SALES | C31: COMPANY | D31: Testing Company Master in Sales CRM | E31: TESTING ISSUE | F31: COMPLETE | J31: 45330 | K31: 45330 | L31: 45330 | M31: 45332 | N31: =IF(L31="",IF(M30="",O30+1,M30+1),L31) -> 45330 | O31: =+N31+P31-1 -> 45330 | P31: =IF(IF(J31="",0,IF(K31="",0,K31-J31))="",0,K31-J31+1) -> 1 | Q31: =IF(L31="",0,IF(M31="",TODAY()-L31,M31-L31+1)) -> 3 | R31: =IF(Q31=0,0,P31-Q31) -> -2
A32: =ROW() - ROW($A$30) + 28 -> 30 | B32: SALES | C32: MANAGE BANK | D32: Testing of Bank master(sales CRM) | E32: TESTING ISSUE | F32: COMPLETE | J32: 45330 | K32: 45330 | L32: 45332 | M32: 45332 | N32: =IF(L32="",IF(M31="",O31+1,M31+1),L32) -> 45332 | O32: =+N32+P32-1 -> 45332 | P32: =IF(IF(J32="",0,IF(K32="",0,K32-J32))="",0,K32-J32+1) -> 1 | Q32: =IF(L32="",0,IF(M32="",TODAY()-L32,M32-L32+1)) -> 1 | R32: =IF(Q32=0,0,P32-Q32) -> 0
A33: =ROW() - ROW($A$30) + 28 -> 31 | B33: SALES | D33: Testing of Bank account(sales CRM),Testing of tax master(sales CRM),Testing of term master(sales CRM),Testing of payment term master(sales CRM). | E33: TESTING ISSUE | F33: COMPLETE | J33: 45331 | K33: 45331 | L33: 45332 | M33: 45332 | N33: =IF(L33="",IF(M32="",O32+1,M32+1),L33) -> 45332 | O33: =+N33+P33-1 -> 45332 | P33: =IF(IF(J33="",0,IF(K33="",0,K33-J33))="",0,K33-J33+1) -> 1 | Q33: =IF(L33="",0,IF(M33="",TODAY()-L33,M33-L33+1)) -> 1 | R33: =IF(Q33=0,0,P33-Q33) -> 0
A34: =ROW() - ROW($A$30) + 28 -> 32 | B34: SALES | C34: LOCATION | D34: Issue fix of location master in sales CRM | E34: TESTING ISSUE | F34: COMPLETE | J34: 45334 | K34: 45334 | L34: 45334 | M34: 45338 | N34: =IF(L34="",IF(M33="",O33+1,M33+1),L34) -> 45334 | O34: =+N34+P34-1 -> 45334 | P34: =IF(IF(J34="",0,IF(K34="",0,K34-J34))="",0,K34-J34+1) -> 1 | Q34: =IF(L34="",0,IF(M34="",TODAY()-L34,M34-L34+1)) -> 5 | R34: =IF(Q34=0,0,P34-Q34) -> -4
A35: =ROW() - ROW($A$30) + 28 -> 33 | B35: SALES | D35: modification in location master village part and area master . | E35: MODIFICATION | F35: COMPLETE | J35: 45337 | K35: 45337 | L35: 45338 | M35: 45338 | N35: =IF(L35="",IF(M34="",O34+1,M34+1),L35) -> 45338 | O35: =+N35+P35-1 -> 45338 | P35: =IF(IF(J35="",0,IF(K35="",0,K35-J35))="",0,K35-J35+1) -> 1 | Q35: =IF(L35="",0,IF(M35="",TODAY()-L35,M35-L35+1)) -> 1 | R35: =IF(Q35=0,0,P35-Q35) -> 0
A36: =ROW() - ROW($A$30) + 28 -> 34 | B36: SALES | D36: All menu set up for reports and analysis the flow . | E36: OTHER | F36: COMPLETE | J36: 45338 | K36: 45339 | L36: 45338 | M36: 45341 | N36: =IF(L36="",IF(M35="",O35+1,M35+1),L36) -> 45338 | O36: =+N36+P36-1 -> 45339 | P36: =IF(IF(J36="",0,IF(K36="",0,K36-J36))="",0,K36-J36+1) -> 2 | Q36: =IF(L36="",0,IF(M36="",TODAY()-L36,M36-L36+1)) -> 4 | R36: =IF(Q36=0,0,P36-Q36) -> -2
